Workbook

Sheet Detailed Results
A1: Table 1. Detailed Results — All Experiments (Raw Counts)
A2: 14 descriptions × 3 LLMs × 3 temperatures × 3 iterations × 2 prompts = 756 experiments | P / R / F1 calculated in 'GT Comparison' sheet
G3: Syntactic evaluation | I3: Syntactic evaluation | K3: Sematic evaluation | M3: Sematic evaluation
G4: DRD | I4: DT | K4: DRD | M4: DT
A5: Source | B5: LLM | C5: Temp | D5: Iter | E5: Prompt | F5: #words | G5: #pred | H5: #correct | I5: #pred | J5: #correct | K5: #pred | L5: #correct | M5: #pred | N5: #correct
A6: Description 01 | B6: Gemini | C6: T=0.2 | D6: 1 | E6: zero | F6: 101 | G6: 7 | H6: 7 | I6: 12 | J6: 12 | K6: =G6 -> 7 | L6: 5 | M6: =I6 -> 12 | N6: 12
B7: Gemini | C7: T=0.2 | D7: 1 | E7: one | G7: 7 | H7: 7 | I7: 12 | J7: 12 | K7: =G7 -> 7 | L7: 5 | M7: =I7 -> 12 | N7: 12
B8: Gemini | C8: T=0.2 | D8: 2 | E8: zero | G8: 7 | H8: 7 | I8: 12 | J8: 12 | K8: =G8 -> 7 | L8: 5 | M8: =I8 -> 12 | N8: 12
B9: Gemini | C9: T=0.2 | D9: 2 | E9: one | G9: 5 | H9: 5 | I9: 12 | J9: 12 | K9: =G9 -> 5 | L9: 3 | M9: =I9 -> 12 | N9: 12
B10: Gemini | C10: T=0.2 | D10: 3 | E10: zero | G10: 7 | H10: 7 | I10: 12 | J10: 12 | K10: =G10 -> 7 | L10: 5 | M10: =I10 -> 12 | N10: 12
B11: Gemini | C11: T=0.2 | D11: 3 | E11: one | G11: 5 | H11: 4 | I11: 12 | J11: 12 | K11: =G11 -> 5 | L11: 5 | M11: =I11 -> 12 | N11: 12
B12: Gemini | C12: T=0.4 | D12: 1 | E12: zero | G12: 7 | H12: 7 | I12: 12 | J12: 12 | K12: =G12 -> 7 | L12: 5 | M12: =I12 -> 12 | N12: 12
B13: Gemini | C13: T=0.4 | D13: 1 | E13: one | G13: 7 | H13: 7 | I13: 12 | J13: 12 | K13: =G13 -> 7 | L13: 5 | M13: =I13 -> 12 | N13: 12
B14: Gemini | C14: T=0.4 | D14: 2 | E14: zero | G14: 5 | H14: 4 | I14: 12 | J14: 12 | K14: =G14 -> 5 | L14: 5 | M14: =I14 -> 12 | N14: 12
B15: Gemini | C15: T=0.4 | D15: 2 | E15: one | G15: 7 | H15: 7 | I15: 12 | J15: 12 | K15: =G15 -> 7 | L15: 5 | M15: =I15 -> 12 | N15: 12
B16: Gemini | C16: T=0.4 | D16: 3 | E16: zero | G16: 5 | H16: 4 | I16: 12 | J16: 12 | K16: =G16 -> 5 | L16: 5 | M16: =I16 -> 12 | N16: 12
B17: Gemini | C17: T=0.4 | D17: 3 | E17: one | G17: 7 | H17: 7 | I17: 12 | J17: 12 | K17: =G17 -> 7 | L17: 5 | M17: =I17 -> 12 | N17: 12
B18: Gemini | C18: T=0.6 | D18: 1 | E18: zero | G18: 5 | H18: 4 | I18: 12 | J18: 12 | K18: =G18 -> 5 | L18: 5 | M18: =I18 -> 12 | N18: 12
... B26: Llama 3 | C26: T=0.2 | D26: 2 | E26: zero | G26: 9 | H26: 9 | I26: 18 | J26: 18 | K26: =G26 -> 9 | L26: 9 | M26: =I26 -> 18 | N26: 18
B27: Llama 3 | C27: T=0.2 | D27: 2 | E27: one | G27: 7 | H27: 7 | I27: 6 | J27: =18-13 -> 5 | K27: =G27 -> 7 | L27: 5 | M27: =I27 -> 6 | N27: 6
B28: Llama 3 | C28: T=0.2 | D28: 3 | E28: zero | G28: 9 | H28: 9 | I28: 18 | J28: 18 | K28: =G28 -> 9 | L28: 9 | M28: =I28 -> 18 | N28: 18
B29: Llama 3 | C29: T=0.2 | D29: 3 | E29: one | G29: 7 | H29: 7 | I29: 6 | J29: 6 | K29: =G29 -> 7 | L29: 5 | M29: =I29 -> 6 | N29: 6
B30: Llama 3 | C30: T=0.4 | D30: 1 | E30: zero | G30: 7 | H30: 7 | I30: 12 | J30: 12 | K30: =G30 -> 7 | L30: 5 | M30: =I30 -> 12 | N30: 12
B31: Llama 3 | C31: T=0.4 | D31: 1 | E31: one | G31: 7 | H31: 7 | I31: 6 | J31: 6 | K31: =G31 -> 7 | L31: 5 | M31: =I31 -> 6 | N31: 6
B32: Llama 3 | C32: T=0.4 | D32: 2 | E32: zero | G32: 7 | H32: 7 | I32: 12 | J32: 12 | K32: =G32 -> 7 | L32: 5 | M32: =I32 -> 12 | N32: 12
B33: Llama 3 | C33: T=0.4 | D33: 2 | E33: one | G33: 7 | H33: 7 | I33: 6 | J33: 6 | K33: =G33 -> 7 | L33: 5 | M33: =I33 -> 6 | N33: 6
B34: Llama 3 | C34: T=0.4 | D34: 3 | E34: zero | G34: 7 | H34: 7 | I34: 12 | J34: 12 | K34: =G34 -> 7 | L34: 5 | M34: =I34 -> 12 | N34: 12
B35: Llama 3 | C35: T=0.4 | D35: 3 | E35: one | G35: 7 | H35: 7 | I35: 6 | J35: 6 | K35: =G35 -> 7 | L35: 5 | M35: =I35 -> 6 | N35: 6
B36: Llama 3 | C36: T=0.6 | D36: 1 | E36: zero | G36: 7 | H36: 7 | I36: 5 | J36: 5 | K36: =G36 -> 7 | L36: 5 | M36: =I36 -> 5 | N36: 5
B37: Llama 3 | C37: T=0.6 | D37: 1 | E37: one | G37: 7 | H37: 7 | I37: 5 | J37: 5 | K37: =G37 -> 7 | L37: 5 | M37: =I37 -> 5 | N37: 5
B38: Llama 3 | C38: T=0.6 | D38: 2 | E38: zero | G38: 7 | H38: 7 | I38: 5 | J38: 5 | K38: =G38 -> 7 | L38: 5 | M38: =I38 -> 5 | N38: 5
B39: Llama 3 | C39: T=0.6 | D39: 2 | E39: one | G39: 7 | H39: 7 | I39: 13 | J39: 13 | K39: =G39 -> 7 | L39: 5 | M39: =I39 -> 13 | N39: 13
... B59: Mistral | C59: T=0.6 | D59: 3 | E59: one | G59: 7 | H59: 7 | I59: 12 | J59: 12 | K59: =G59 -> 7 | L59: 4 | M59: =I59 -> 12 | N59: 12
A60: Description 02 | B60: Gemini | C60: T=0.2 | D60: 1 | E60: zero | F60: 38 | G60: 9 | H60: 9 | I60: 19 | J60: 19 | K60: 9 | L60: 9 | M60: 19 | N60: 15
B61: Gemini | C61: T=0.2 | D61: 1 | E61: one | G61: 9 | H61: 9 | I61: 19 | J61: 19 | K61: =G61 -> 9 | L61: 9 | M61: =I61 -> 19 | N61: 15
B62: Gemini | C62: T=0.2 | D62: 2 | E62: zero | G62: 9 | H62: 9 | I62: 16 | J62: 16 | K62: =G62 -> 9 | L62: 9 | M62: =I62 -> 16 | N62: 12
B63: Gemini | C63: T=0.2 | D63: 2 | E63: one | G63: 9 | H63: 9 | I63: 19 | J63: 19 | K63: =G63 -> 9 | L63: 9 | M63: =I63 -> 19 | N63: 16
B64: Gemini | C64: T=0.2 | D64: 3 | E64: zero | G64: 9 | H64: 9 | I64: 15 | J64: 15 | K64: =G64 -> 9 | L64: 9 | M64: =I64 -> 15 | N64: 10
B65: Gemini | C65: T=0.2 | D65: 3 | E65: one | G65: 9 | H65: 9 | I65: 19 | J65: 19 | K65: =G65 -> 9 | L65: 9 | M65: =I65 -> 19 | N65: 16
B66: Gemini | C66: T=0.4 | D66: 1 | E66: zero | G66: 9 | H66: 9 | I66: 19 | J66: 19 | K66: =G66 -> 9 | L66: 9 | M66: =I66 -> 19 | N66: 19
...

Sheet GT Input
A1: GT Input — Ground-Truth Reference Counts (enter once per description; values flow automatically to GT Comparison)
A2: Description | C2: Syntactic — DRD | D2: Syntactic — Decision Table | E2: Semantic — DRD | F2: Semantic — Decision Table
A3: Description | B3: #words | C3: #truth | D3: #truth | E3: #truth | F3: #truth
A4: Description 01 | B4: 101 | C4: 9 | D4: =6+12 -> 18 | E4: =C4 -> 9 | F4: =D4 -> 18
A5: Description 02 | B5: 38 | C5: 9 | D5: 15 | E5: =C5 -> 9 | F5: =D5 -> 15
A6: Description 03 | B6: 51 | C6: 11 | D6: =11+8 -> 19 | E6: =C6 -> 11 | F6: =D6 -> 19
A7: Description 04 | B7: 44 | C7: 7 | D7: 38 | E7: =C7 -> 7 | F7: =D7 -> 38
A8: Description 05 | B8: 59 | C8: 3 | D8: 9 | E8: =C8 -> 3 | F8: =D8 -> 9
A9: Description 06 | B9: 85 | C9: 9 | D9: =2+2+9 -> 13 | E9: =C9 -> 9 | F9: =D9 -> 13
A10: Description 07 | B10: 90 | C10: 7 | D10: 18 | E10: =C10 -> 7 | F10: =D10 -> 18
A11: Description 08 | B11: 72 | C11: 7 | D11: 11 | E11: =C11 -> 7 | F11: =D11 -> 11
A12: Description 09 | B12: 65 | C12: 9 | D12: 12 | E12: =C12 -> 9 | F12: =D12 -> 12
A13: Description 10 | B13: 48 | C13: 7 | D13: 14 | E13: =C13 -> 7 | F13: =D13 -> 14
A14: Description 11 | B14: 55 | C14: 15 | D14: =9+6+7+10 -> 32 | E14: =C14 -> 15 | F14: =D14 -> 32
A15: Description 12 | B15: 63 | C15: 13 | D15: =10+8 -> 18 | E15: =C15 -> 13 | F15: =D15 -> 18
A16: Description 13 | B16: 77 | C16: 7 | D16: =9+7 -> 16 | E16: =C16 -> 7 | F16: =D16 -> 16
A17: Description 14 | B17: 82 | C17: 9 | D17: =11+9 -> 20 | E17: =C17 -> 9 | F17: =D17 -> 20
A19: INSTRUCTIONS

Sheet GT Comparison
A1: Ground-Truth vs. Predicted · Score Comparison Table
A2: 🟩 Green (cols F–Q) = GT values auto-linked from 'GT Input' sheet — enter there once · 🟦 Blue = predicted counts from 'Detailed Results' · P/R/F1 computed here · 🟪 Purple delta: positive=model beats GT · negative=below GT
A3: EXPERIMENT CONFIG | F3: GROUND-TRUTH — Syntactic | H3: GROUND-TRUTH — Semantic | J3: Syntactic evaluation | O3: Syntactic evaluation | T3: Semantic evaluation | Y3: Semantic evaluation
F4: DRD | G4: DT | H4: DRD | I4: DT | J4: DRD | O4: DT | T4: DRD | Y4: DT
A5: Source | B5: LLM | C5: Temp | D5: Iter | E5: Prompt | F5: GT #truth | G5: GT #truth | H5: GT #truth | I5: GT #truth | J5: #pred | K5: #correct | L5: P | M5: R | N5: F1 | O5: #pred | P5: #correct | Q5: P | R5: R | S5: F1 | T5: #pred | U5: #correct | V5: P | W5: R | X5: F1 | Y5: #pred | Z5: #correct | AA5: P | AB5: R | AC5: F1
A6: Description 01 | B6: Gemini | C6: T=0.2 | D6: 1 | E6: zero | F6: ='GT Input'!C4 -> 9 | G6: ='GT Input'!D4 -> 18 | H6: ='GT Input'!E4 -> 9 | I6: ='GT Input'!F4 -> 18 | J6: 7 | K6: 7 | L6: =IFERROR(K6/J6,"") -> 1 | M6: =IFERROR(K6/F6,"") -> 0.77777778 | N6: =IFERROR(2*L6*M6/(L6+M6),"") -> 0.875 | O6: ='Detailed Results'!I6 -> 12 | P6: ='Detailed Results'!J6 -> 12 | Q6: =IFERROR(P6/O6,"") -> 1 | R6: =IFERROR(P6/G6,"") -> 0.66666667 | S6: =IFERROR(2*Q6*R6/(Q6+R6),"") -> 0.8 | T6: ='Detailed Results'!K6 -> 7 | U6: ='Detailed Results'!L6 -> 5 | V6: =IFERROR(U6/T6,"") -> 0.71428571 | W6: =IFERROR(U6/H6,"") -> 0.55555556 | X6: =IFERROR(2*V6*W6/(V6+W6),"") -> 0.625 | Y6: ='Detailed Results'!M6 -> 12 | Z6: ='Detailed Results'!N6 -> 12 | AA6: =IFERROR(Z6/Y6,"") -> 1 | AB6: =IFERROR(Z6/I6,"") -> 0.66666667 | AC6: =IFERROR(2*AA6*AB6/(AA6+AB6),"") -> 0.8
B7: Gemini | C7: T=0.2 | D7: 1 | E7: one | F7: ='GT Input'!C4 -> 9 | G7: ='GT Input'!D4 -> 18 | H7: ='GT Input'!E4 -> 9 | I7: ='GT Input'!F4 -> 18 | J7: 7 | K7: 7 | L7: =IFERROR(K7/J7,"") -> 1 | M7: =IFERROR(K7/F7,"") -> 0.77777778 | N7: =IFERROR(2*L7*M7/(L7+M7),"") -> 0.875 | O7: ='Detailed Results'!I7 -> 12 | P7: ='Detailed Results'!J7 -> 12 | Q7: =IFERROR(P7/O7,"") -> 1 | R7: =IFERROR(P7/G7,"") -> 0.66666667 | S7: =IFERROR(2*Q7*R7/(Q7+R7),"") -> 0.8 | T7: ='Detailed Results'!K7 -> 7 | U7: ='Detailed Results'!L7 -> 5 | V7: =IFERROR(U7/T7,"") -> 0.71428571 | W7: =IFERROR(U7/H7,"") -> 0.55555556 | X7: =IFERROR(2*V7*W7/(V7+W7),"") -> 0.625 | Y7: ='Detailed Results'!M7 -> 12 | Z7: ='Detailed Results'!N7 -> 12 | AA7: =IFERROR(Z7/Y7,"") -> 1 | AB7: =IFERROR(Z7/I7,"") -> 0.66666667 | AC7: =IFERROR(2*AA7*AB7/(AA7+AB7),"") -> 0.8
B8: Gemini | C8: T=0.2 | D8: 2 | E8: zero | F8: ='GT Input'!C4 -> 9 | G8: ='GT Input'!D4 -> 18 | H8: ='GT Input'!E4 -> 9 | I8: ='GT Input'!F4 -> 18 | J8: 7 | K8: ='Detailed Results'!H8 -> 7 | L8: 0.96422764 | M8: =IFERROR(K8/F8,"") -> 0.77777778 | N8: 0.88181818 | O8: ='Detailed Results'!I8 -> 12 | P8: ='Detailed Results'!J8 -> 12 | Q8: =IFERROR(P8/O8,"") -> 1 | R8: =IFERROR(P8/G8,"") -> 0.66666667 | S8: =IFERROR(2*Q8*R8/(Q8+R8),"") -> 0.8 | T8: ='Detailed Results'!K8 -> 7 | U8: ='Detailed Results'!L8 -> 5 | V8: =IFERROR(U8/T8,"") -> 0.71428571 | W8: =IFERROR(U8/H8,"") -> 0.55555556 | X8: =IFERROR(2*V8*W8/(V8+W8),"") -> 0.625 | Y8: ='Detailed Results'!M8 -> 12 | Z8: ='Detailed Results'!N8 -> 12 | AA8: =IFERROR(Z8/Y8,"") -> 1 | AB8: =IFERROR(Z8/I8,"") -> 0.66666667 | AC8: =IFERROR(2*AA8*AB8/(AA8+AB8),"") -> 0.8
B9: Gemini | C9: T=0.2 | D9: 2 | E9: one | F9: ='GT Input'!C4 -> 9 | G9: ='GT Input'!D4 -> 18 | H9: ='GT Input'!E4 -> 9 | I9: ='GT Input'!F4 -> 18 | J9: 5 | K9: ='Detailed Results'!H9 -> 5 | L9: 0.98064266 | M9: =IFERROR(K9/F9,"") -> 0.55555556 | N9: 0.90695808 | O9: ='Detailed Results'!I9 -> 12 | P9: ='Detailed Results'!J9 -> 12 | Q9: =IFERROR(P9/O9,"") -> 1 | R9: =IFERROR(P9/G9,"") -> 0.66666667 | S9: =IFERROR(2*Q9*R9/(Q9+R9),"") -> 0.8 | T9: ='Detailed Results'!K9 -> 5 | U9: ='Detailed Results'!L9 -> 3 | V9: =IFERROR(U9/T9,"") -> 0.6 | W9: =IFERROR(U9/H9,"") -> 0.33333333 | X9: =IFERROR(2*V9*W9/(V9+W9),"") -> 0.42857143 | Y9: ='Detailed Results'!M9 -> 12 | Z9: ='Detailed Results'!N9 -> 12 | AA9: =IFERROR(Z9/Y9,"") -> 1 | AB9: =IFERROR(Z9/I9,"") -> 0.66666667 | AC9: =IFERROR(2*AA9*AB9/(AA9+AB9),"") -> 0.8
B10: Gemini | C10: T=0.2 | D10: 3 | E10: zero | F10: ='GT Input'!C4 -> 9 | G10: ='GT Input'!D4 -> 18 | H10: ='GT Input'!E4 -> 9 | I10: ='GT Input'!F4 -> 18 | J10: 7 | K10: ='Detailed Results'!H10 -> 7 | L10: 0.97333333 | M10: =IFERROR(K10/F10,"") -> 0.77777778 | N10: 0.90369859 | O10: ='Detailed Results'!I10 -> 12 | P10: ='Detailed Results'!J10 -> 12 | Q10: =IFERROR(P10/O10,"") -> 1 | R10: =IFERROR(P10/G10,"") -> 0.66666667 | S10: =IFERROR(2*Q10*R10/(Q10+R10),"") -> 0.8 | T10: ='Detailed Results'!K10 -> 7 | U10: ='Detailed Results'!L10 -> 5 | V10: =IFERROR(U10/T10,"") -> 0.71428571 | W10: =IFERROR(U10/H10,"") -> 0.55555556 | X10: =IFERROR(2*V10*W10/(V10+W10),"") -> 0.625 | Y10: ='Detailed Results'!M10 -> 12 | Z10: ='Detailed Results'!N10 -> 12 | AA10: =IFERROR(Z10/Y10,"") -> 1 | AB10: =IFERROR(Z10/I10,"") -> 0.66666667 | AC10: =IFERROR(2*AA10*AB10/(AA10+AB10),"") -> 0.8
B11: Gemini | C11: T=0.2 | D11: 3 | E11: one | F11: ='GT Input'!C4 -> 9 | G11: ='GT Input'!D4 -> 18 | H11: ='GT Input'!E4 -> 9 | I11: ='GT Input'!F4 -> 18 | J11: 5 | K11: 3 | L11: =IFERROR(K11/J11,"") -> 0.6 | M11: =IFERROR(K11/F11,"") -> 0.33333333 | N11: =IFERROR(2*L11*M11/(L11+M11),"") -> 0.42857143 | O11: ='Detailed Results'!I11 -> 12 | P11: ='Detailed Results'!J11 -> 12 | Q11: =IFERROR(P11/O11,"") -> 1 | R11: =IFERROR(P11/G11,"") -> 0.66666667 | S11: =IFERROR(2*Q11*R11/(Q11+R11),"") -> 0.8 | T11: ='Detailed Results'!K11 -> 5 | U11: ='Detailed Results'!L11 -> 5 | V11: =IFERROR(U11/T11,"") -> 1 | W11: =IFERROR(U11/H11,"") -> 0.55555556 | X11: =IFERROR(2*V11*W11/(V11+W11),"") -> 0.71428571 | Y11: ='Detailed Results'!M11 -> 12 | Z11: ='Detailed Results'!N11 -> 12 | AA11: =IFERROR(Z11/Y11,"") -> 1 | AB11: =IFERROR(Z11/I11,"") -> 0.66666667 | AC11: =IFERROR(2*AA11*AB11/(AA11+AB11),"") -> 0.8
B12: Gemini | C12: T=0.4 | D12: 1 | E12: zero | F12: ='GT Input'!C4 -> 9 | G12: ='GT Input'!D4 -> 18 | H12: ='GT Input'!E4 -> 9 | I12: ='GT Input'!F4 -> 18 | J12: 7 | K12: 7 | L12: =IFERROR(K12/J12,"") -> 1 | M12: =IFERROR(K12/F12,"") -> 0.77777778 | N12: =IFERROR(2*L12*M12/(L12+M12),"") -> 0.875 | O12: ='Detailed Results'!I12 -> 12 | P12: ='Detailed Results'!J12 -> 12 | Q12: =IFERROR(P12/O12,"") -> 1 | R12: =IFERROR(P12/G12,"") -> 0.66666667 | S12: =IFERROR(2*Q12*R12/(Q12+R12),"") -> 0.8 | T12: ='Detailed Results'!K12 -> 7 | U12: ='Detailed Results'!L12 -> 5 | V12: =IFERROR(U12/T12,"") -> 0.71428571 | W12: =IFERROR(U12/H12,"") -> 0.55555556 | X12: =IFERROR(2*V12*W12/(V12+W12),"") -> 0.625 | Y12: ='Detailed Results'!M12 -> 12 | Z12: ='Detailed Results'!N12 -> 12 | AA12: =IFERROR(Z12/Y12,"") -> 1 | AB12: =IFERROR(Z12/I12,"") -> 0.66666667 | AC12: =IFERROR(2*AA12*AB12/(AA12+AB12),"") -> 0.8
B13: Gemini | C13: T=0.4 | D13: 1 | E13: one | F13: ='GT Input'!C4 -> 9 | G13: ='GT Input'!D4 -> 18 | H13: ='GT Input'!E4 -> 9 | I13: ='GT Input'!F4 -> 18 | J13: 7 | K13: 7 | L13: =IFERROR(K13/J13,"") -> 1 | M13: =IFERROR(K13/F13,"") -> 0.77777778 | N13: =IFERROR(2*L13*M13/(L13+M13),"") -> 0.875 | O13: ='Detailed Results'!I13 -> 12 | P13: ='Detailed Results'!J13 -> 12 | Q13: =IFERROR(P13/O13,"") -> 1 | R13: =IFERROR(P13/G13,"") -> 0.66666667 | S13: =IFERROR(2*Q13*R13/(Q13+R13),"") -> 0.8 | T13: ='Detailed Results'!K13 -> 7 | U13: ='Detailed Results'!L13 -> 5 | V13: =IFERROR(U13/T13,"") -> 0.71428571 | W13: =IFERROR(U13/H13,"") -> 0.55555556 | X13: =IFERROR(2*V13*W13/(V13+W13),"") -> 0.625 | Y13: ='Detailed Results'!M13 -> 12 | Z13: ='Detailed Results'!N13 -> 12 | AA13: =IFERROR(Z13/Y13,"") -> 1 | AB13: =IFERROR(Z13/I13,"") -> 0.66666667 | AC13: =IFERROR(2*AA13*AB13/(AA13+AB13),"") -> 0.8
B14: Gemini | C14: T=0.4 | D14: 2 | E14: zero | F14: ='GT Input'!C4 -> 9 | G14: ='GT Input'!D4 -> 18 | H14: ='GT Input'!E4 -> 9 | I14: ='GT Input'!F4 -> 18 | J14: 5 | K14: 3 | L14: =IFERROR(K14/J14,"") -> 0.6 | M14: =IFERROR(K14/F14,"") -> 0.33333333 | N14: =IFERROR(2*L14*M14/(L14+M14),"") -> 0.42857143 | O14: ='Detailed Results'!I14 -> 12 | P14: ='Detailed Results'!J14 -> 12 | Q14: =IFERROR(P14/O14,"") -> 1 | R14: =IFERROR(P14/G14,"") -> 0.66666667 | S14: =IFERROR(2*Q14*R14/(Q14+R14),"") -> 0.8 | T14: ='Detailed Results'!K14 -> 5 | U14: ='Detailed Results'!L14 -> 5 | V14: =IFERROR(U14/T14,"") -> 1 | W14: =IFERROR(U14/H14,"") -> 0.55555556 | X14: =IFERROR(2*V14*W14/(V14+W14),"") -> 0.71428571 | Y14: ='Detailed Results'!M14 -> 12 | Z14: ='Detailed Results'!N14 -> 12 | AA14: =IFERROR(Z14/Y14,"") -> 1 | AB14: =IFERROR(Z14/I14,"") -> 0.66666667 | AC14: =IFERROR(2*AA14*AB14/(AA14+AB14),"") -> 0.8
B15: Gemini | C15: T=0.4 | D15: 2 | E15: one | F15: ='GT Input'!C4 -> 9 | G15: ='GT Input'!D4 -> 18 | H15: ='GT Input'!E4 -> 9 | I15: ='GT Input'!F4 -> 18 | J15: 7 | K15: 7 | L15: =IFERROR(K15/J15,"") -> 1 | M15: =IFERROR(K15/F15,"") -> 0.77777778 | N15: =IFERROR(2*L15*M15/(L15+M15),"") -> 0.875 | O15: ='Detailed Results'!I15 -> 12 | P15: ='Detailed Results'!J15 -> 12 | Q15: =IFERROR(P15/O15,"") -> 1 | R15: =IFERROR(P15/G15,"") -> 0.66666667 | S15: =IFERROR(2*Q15*R15/(Q15+R15),"") -> 0.8 | T15: ='Detailed Results'!K15 -> 7 | U15: ='Detailed Results'!L15 -> 5 | V15: =IFERROR(U15/T15,"") -> 0.71428571 | W15: =IFERROR(U15/H15,"") -> 0.55555556 | X15: =IFERROR(2*V15*W15/(V15+W15),"") -> 0.625 | Y15: ='Detailed Results'!M15 -> 12 | Z15: ='Detailed Results'!N15 -> 12 | AA15: =IFERROR(Z15/Y15,"") -> 1 | AB15: =IFERROR(Z15/I15,"") -> 0.66666667 | AC15: =IFERROR(2*AA15*AB15/(AA15+AB15),"") -> 0.8
B16: Gemini | C16: T=0.4 | D16: 3 | E16: zero | F16: ='GT Input'!C4 -> 9 | G16: ='GT Input'!D4 -> 18 | H16: ='GT Input'!E4 -> 9 | I16: ='GT Input'!F4 -> 18 | J16: 5 | K16: 3 | L16: =IFERROR(K16/J16,"") -> 0.6 | M16: =IFERROR(K16/F16,"") -> 0.33333333 | N16: =IFERROR(2*L16*M16/(L16+M16),"") -> 0.42857143 | O16: ='Detailed Results'!I16 -> 12 | P16: ='Detailed Results'!J16 -> 12 | Q16: =IFERROR(P16/O16,"") -> 1 | R16: =IFERROR(P16/G16,"") -> 0.66666667 | S16: =IFERROR(2*Q16*R16/(Q16+R16),"") -> 0.8 | T16: ='Detailed Results'!K16 -> 5 | U16: ='Detailed Results'!L16 -> 5 | V16: =IFERROR(U16/T16,"") -> 1 | W16: =IFERROR(U16/H16,"") -> 0.55555556 | X16: =IFERROR(2*V16*W16/(V16+W16),"") -> 0.71428571 | Y16: ='Detailed Results'!M16 -> 12 | Z16: ='Detailed Results'!N16 -> 12 | AA16: =IFERROR(Z16/Y16,"") -> 1 | AB16: =IFERROR(Z16/I16,"") -> 0.66666667 | AC16: =IFERROR(2*AA16*AB16/(AA16+AB16),"") -> 0.8
B17: Gemini | C17: T=0.4 | D17: 3 | E17: one | F17: ='GT Input'!C4 -> 9 | G17: ='GT Input'!D4 -> 18 | H17: ='GT Input'!E4 -> 9 | I17: ='GT Input'!F4 -> 18 | J17: 7 | K17: 7 | L17: =IFERROR(K17/J17,"") -> 1 | M17: =IFERROR(K17/F17,"") -> 0.77777778 | N17: =IFERROR(2*L17*M17/(L17+M17),"") -> 0.875 | O17: ='Detailed Results'!I17 -> 12 | P17: ='Detailed Results'!J17 -> 12 | Q17: =IFERROR(P17/O17,"") -> 1 | R17: =IFERROR(P17/G17,"") -> 0.66666667 | S17: =IFERROR(2*Q17*R17/(Q17+R17),"") -> 0.8 | T17: ='Detailed Results'!K17 -> 7 | U17: ='Detailed Results'!L17 -> 5 | V17: =IFERROR(U17/T17,"") -> 0.71428571 | W17: =IFERROR(U17/H17,"") -> 0.55555556 | X17: =IFERROR(2*V17*W17/(V17+W17),"") -> 0.625 | Y17: ='Detailed Results'!M17 -> 12 | Z17: ='Detailed Results'!N17 -> 12 | AA17: =IFERROR(Z17/Y17,"") -> 1 | AB17: =IFERROR(Z17/I17,"") -> 0.66666667 | AC17: =IFERROR(2*AA17*AB17/(AA17+AB17),"") -> 0.8
B18: Gemini | C18: T=0.6 | D18: 1 | E18: zero | F18: ='GT Input'!C4 -> 9 | G18: ='GT Input'!D4 -> 18 | H18: ='GT Input'!E4 -> 9 | I18: ='GT Input'!F4 -> 18 | J18: 5 | K18: 3 | L18: =IFERROR(K18/J18,"") -> 0.6 | M18: =IFERROR(K18/F18,"") -> 0.33333333 | N18: =IFERROR(2*L18*M18/(L18+M18),"") -> 0.42857143 | O18: ='Detailed Results'!I18 -> 12 | P18: ='Detailed Results'!J18 -> 12 | Q18: =IFERROR(P18/O18,"") -> 1 | R18: =IFERROR(P18/G18,"") -> 0.66666667 | S18: =IFERROR(2*Q18*R18/(Q18+R18),"") -> 0.8 | T18: ='Detailed Results'!K18 -> 5 | U18: ='Detailed Results'!L18 -> 5 | V18: =IFERROR(U18/T18,"") -> 1 | W18: =IFERROR(U18/H18,"") -> 0.55555556 | X18: =IFERROR(2*V18*W18/(V18+W18),"") -> 0.71428571 | Y18: ='Detailed Results'!M18 -> 12 | Z18: ='Detailed Results'!N18 -> 12 | AA18: =IFERROR(Z18/Y18,"") -> 1 | AB18: =IFERROR(Z18/I18,"") -> 0.66666667 | AC18: =IFERROR(2*AA18*AB18/(AA18+AB18),"") -> 0.8
B19: Gemini | C19: T=0.6 | D19: 1 | E19: one | F19: ='GT Input'!C4 -> 9 | G19: ='GT Input'!D4 -> 18 | H19: ='GT Input'!E4 -> 9 | I19: ='GT Input'!F4 -> 18 | J19: 7 | K19: 7 | L19: =IFERROR(K19/J19,"") -> 1 | M19: =IFERROR(K19/F19,"") -> 0.77777778 | N19: =IFERROR(2*L19*M19/(L19+M19),"") -> 0.875 | O19: ='Detailed Results'!I19 -> 12 | P19: ='Detailed Results'!J19 -> 12 | Q19: =IFERROR(P19/O19,"") -> 1 | R19: =IFERROR(P19/G19,"") -> 0.66666667 | S19: =IFERROR(2*Q19*R19/(Q19+R19),"") -> 0.8 | T19: ='Detailed Results'!K19 -> 7 | U19: ='Detailed Results'!L19 -> 5 | V19: =IFERROR(U19/T19,"") -> 0.71428571 | W19: =IFERROR(U19/H19,"") -> 0.55555556 | X19: =IFERROR(2*V19*W19/(V19+W19),"") -> 0.625 | Y19: ='Detailed Results'!M19 -> 12 | Z19: ='Detailed Results'!N19 -> 12 | AA19: =IFERROR(Z19/Y19,"") -> 1 | AB19: =IFERROR(Z19/I19,"") -> 0.66666667 | AC19: =IFERROR(2*AA19*AB19/(AA19+AB19),"") -> 0.8
B20: Gemini | C20: T=0.6 | D20: 2 | E20: zero | F20: ='GT Input'!C4 -> 9 | G20: ='GT Input'!D4 -> 18 | H20: ='GT Input'!E4 -> 9 | I20: ='GT Input'!F4 -> 18 | J20: 5 | K20: 3 | L20: =IFERROR(K20/J20,"") -> 0.6 | M20: =IFERROR(K20/F20,"") -> 0.33333333 | N20: =IFERROR(2*L20*M20/(L20+M20),"") -> 0.42857143 | O20: ='Detailed Results'!I20 -> 12 | P20: ='Detailed Results'!J20 -> 12 | Q20: =IFERROR(P20/O20,"") -> 1 | R20: =IFERROR(P20/G20,"") -> 0.66666667 | S20: =IFERROR(2*Q20*R20/(Q20+R20),"") -> 0.8 | T20: ='Detailed Results'!K20 -> 5 | U20: ='Detailed Results'!L20 -> 5 | V20: =IFERROR(U20/T20,"") -> 1 | W20: =IFERROR(U20/H20,"") -> 0.55555556 | X20: =IFERROR(2*V20*W20/(V20+W20),"") -> 0.71428571 | Y20: ='Detailed Results'!M20 -> 12 | Z20: ='Detailed Results'!N20 -> 12 | AA20: =IFERROR(Z20/Y20,"") -> 1 | AB20: =IFERROR(Z20/I20,"") -> 0.66666667 | AC20: =IFERROR(2*AA20*AB20/(AA20+AB20),"") -> 0.8
B21: Gemini | C21: T=0.6 | D21: 2 | E21: one | F21: ='GT Input'!C4 -> 9 | G21: ='GT Input'!D4 -> 18 | H21: ='GT Input'!E4 -> 9 | I21: ='GT Input'!F4 -> 18 | J21: 7 | K21: 7 | L21: =IFERROR(K21/J21,"") -> 1 | M21: =IFERROR(K21/F21,"") -> 0.77777778 | N21: =IFERROR(2*L21*M21/(L21+M21),"") -> 0.875 | O21: ='Detailed Results'!I21 -> 12 | P21: ='Detailed Results'!J21 -> 12 | Q21: =IFERROR(P21/O21,"") -> 1 | R21: =IFERROR(P21/G21,"") -> 0.66666667 | S21: =IFERROR(2*Q21*R21/(Q21+R21),"") -> 0.8 | T21: ='Detailed Results'!K21 -> 7 | U21: ='Detailed Results'!L21 -> 5 | V21: =IFERROR(U21/T21,"") -> 0.71428571 | W21: =IFERROR(U21/H21,"") -> 0.55555556 | X21: =IFERROR(2*V21*W21/(V21+W21),"") -> 0.625 | Y21: ='Detailed Results'!M21 -> 12 | Z21: ='Detailed Results'!N21 -> 12 | AA21: =IFERROR(Z21/Y21,"") -> 1 | AB21: =IFERROR(Z21/I21,"") -> 0.66666667 | AC21: =IFERROR(2*AA21*AB21/(AA21+AB21),"") -> 0.8
B22: Gemini | C22: T=0.6 | D22: 3 | E22: zero | F22: ='GT Input'!C4 -> 9 | G22: ='GT Input'!D4 -> 18 | H22: ='GT Input'!E4 -> 9 | I22: ='GT Input'!F4 -> 18 | J22: 7 | K22: 7 | L22: =IFERROR(K22/J22,"") -> 1 | M22: =IFERROR(K22/F22,"") -> 0.77777778 | N22: =IFERROR(2*L22*M22/(L22+M22),"") -> 0.875 | O22: ='Detailed Results'!I22 -> 12 | P22: ='Detailed Results'!J22 -> 12 | Q22: =IFERROR(P22/O22,"") -> 1 | R22: =IFERROR(P22/G22,"") -> 0.66666667 | S22: =IFERROR(2*Q22*R22/(Q22+R22),"") -> 0.8 | T22: ='Detailed Results'!K22 -> 7 | U22: ='Detailed Results'!L22 -> 5 | V22: =IFERROR(U22/T22,"") -> 0.71428571 | W22: =IFERROR(U22/H22,"") -> 0.55555556 | X22: =IFERROR(2*V22*W22/(V22+W22),"") -> 0.625 | Y22: ='Detailed Results'!M22 -> 12 | Z22: ='Detailed Results'!N22 -> 12 | AA22: =IFERROR(Z22/Y22,"") -> 1 | AB22: =IFERROR(Z22/I22,"") -> 0.66666667 | AC22: =IFERROR(2*AA22*AB22/(AA22+AB22),"") -> 0.8
B23: Gemini | C23: T=0.6 | D23: 3 | E23: one | F23: ='GT Input'!C4 -> 9 | G23: ='GT Input'!D4 -> 18 | H23: ='GT Input'!E4 -> 9 | I23: ='GT Input'!F4 -> 18 | J23: 5 | K23: 2 | L23: =IFERROR(K23/J23,"") -> 0.4 | M23: =IFERROR(K23/F23,"") -> 0.22222222 | N23: =IFERROR(2*L23*M23/(L23+M23),"") -> 0.28571429 | O23: ='Detailed Results'!I23 -> 12 | P23: ='Detailed Results'!J23 -> 12 | Q23: =IFERROR(P23/O23,"") -> 1 | R23: =IFERROR(P23/G23,"") -> 0.66666667 | S23: =IFERROR(2*Q23*R23/(Q23+R23),"") -> 0.8 | T23: ='Detailed Results'!K23 -> 5 | U23: ='Detailed Results'!L23 -> 3 | V23: =IFERROR(U23/T23,"") -> 0.6 | W23: =IFERROR(U23/H23,"") -> 0.33333333 | X23: =IFERROR(2*V23*W23/(V23+W23),"") -> 0.42857143 | Y23: ='Detailed Results'!M23 -> 12 | Z23: ='Detailed Results'!N23 -> 12 | AA23: =IFERROR(Z23/Y23,"") -> 1 | AB23: =IFERROR(Z23/I23,"") -> 0.66666667 | AC23: =IFERROR(2*AA23*AB23/(AA23+AB23),"") -> 0.8
B24: Llama 3 | C24: T=0.2 | D24: 1 | E24: zero | F24: ='GT Input'!C4 -> 9 | G24: ='GT Input'!D4 -> 18 | H24: ='GT Input'!E4 -> 9 | I24: ='GT Input'!F4 -> 18 | J24: ='Detailed Results'!G24 -> 9 | K24: ='Detailed Results'!H24 -> 9 | L24: =IFERROR(K24/J24,"") -> 1 | M24: =IFERROR(K24/F24,"") -> 1 | N24: =IFERROR(2*L24*M24/(L24+M24),"") -> 1 | O24: ='Detailed Results'!I24 -> 18 | P24: ='Detailed Results'!J24 -> 18 | Q24: =IFERROR(P24/O24,"") -> 1 | R24: =IFERROR(P24/G24,"") -> 1 | S24: =IFERROR(2*Q24*R24/(Q24+R24),"") -> 1 | T24: ='Detailed Results'!K24 -> 9 | U24: ='Detailed Results'!L24 -> 9 | V24: =IFERROR(U24/T24,"") -> 1 | W24: =IFERROR(U24/H24,"") -> 1 | X24: =IFERROR(2*V24*W24/(V24+W24),"") -> 1 | Y24: ='Detailed Results'!M24 -> 18 | Z24: ='Detailed Results'!N24 -> 18 | AA24: =IFERROR(Z24/Y24,"") -> 1 | AB24: =IFERROR(Z24/I24,"") -> 1 | AC24: =IFERROR(2*AA24*AB24/(AA24+AB24),"") -> 1
B25: Llama 3 | C25: T=0.2 | D25: 1 | E25: one | F25: ='GT Input'!C4 -> 9 | G25: ='GT Input'!D4 -> 18 | H25: ='GT Input'!E4 -> 9 | I25: ='GT Input'!F4 -> 18 | J25: 7 | K25: 7 | L25: =IFERROR(K25/J25,"") -> 1 | M25: =IFERROR(K25/F25,"") -> 0.77777778 | N25: =IFERROR(2*L25*M25/(L25+M25),"") -> 0.875 | O25: ='Detailed Results'!I25 -> 6 | P25: ='Detailed Results'!J25 -> 6 | Q25: =IFERROR(P25/O25,"") -> 1 | R25: =IFERROR(P25/G25,"") -> 0.33333333 | S25: =IFERROR(2*Q25*R25/(Q25+R25),"") -> 0.5 | T25: ='Detailed Results'!K25 -> 7 | U25: ='Detailed Results'!L25 -> 5 | V25: =IFERROR(U25/T25,"") -> 0.71428571 | W25: =IFERROR(U25/H25,"") -> 0.55555556 | X25: =IFERROR(2*V25*W25/(V25+W25),"") -> 0.625 | Y25: ='Detailed Results'!M25 -> 6 | Z25: ='Detailed Results'!N25 -> 6 | AA25: =IFERROR(Z25/Y25,"") -> 1 | AB25: =IFERROR(Z25/I25,"") -> 0.33333333 | AC25: =IFERROR(2*AA25*AB25/(AA25+AB25),"") -> 0.5
B26: Llama 3 | C26: T=0.2 | D26: 2 | E26: zero | F26: ='GT Input'!C4 -> 9 | G26: ='GT Input'!D4 -> 18 | H26: ='GT Input'!E4 -> 9 | I26: ='GT Input'!F4 -> 18 | J26: 9 | K26: 9 | L26: =IFERROR(K26/J26,"") -> 1 | M26: =IFERROR(K26/F26,"") -> 1 | N26: =IFERROR(2*L26*M26/(L26+M26),"") -> 1 | O26: ='Detailed Results'!I26 -> 18 | P26: ='Detailed Results'!J26 -> 18 | Q26: =IFERROR(P26/O26,"") -> 1 | R26: =IFERROR(P26/G26,"") -> 1 | S26: =IFERROR(2*Q26*R26/(Q26+R26),"") -> 1 | T26: ='Detailed Results'!K26 -> 9 | U26: ='Detailed Results'!L26 -> 9 | V26: =IFERROR(U26/T26,"") -> 1 | W26: =IFERROR(U26/H26,"") -> 1 | X26: =IFERROR(2*V26*W26/(V26+W26),"") -> 1 | Y26: ='Detailed Results'!M26 -> 18 | Z26: ='Detailed Results'!N26 -> 18 | AA26: =IFERROR(Z26/Y26,"") -> 1 | AB26: =IFERROR(Z26/I26,"") -> 1 | AC26: =IFERROR(2*AA26*AB26/(AA26+AB26),"") -> 1
B27: Llama 3 | C27: T=0.2 | D27: 2 | E27: one | F27: ='GT Input'!C4 -> 9 | G27: ='GT Input'!D4 -> 18 | H27: ='GT Input'!E4 -> 9 | I27: ='GT Input'!F4 -> 18 | J27: 7 | K27: 7 | L27: =IFERROR(K27/J27,"") -> 1 | M27: =IFERROR(K27/F27,"") -> 0.77777778 | N27: =IFERROR(2*L27*M27/(L27+M27),"") -> 0.875 | O27: ='Detailed Results'!I27 -> 6 | P27: ='Detailed Results'!J27 -> 5 | Q27: =IFERROR(P27/O27,"") -> 0.83333333 | R27: =IFERROR(P27/G27,"") -> 0.27777778 | S27: =IFERROR(2*Q27*R27/(Q27+R27),"") -> 0.41666667 | T27: ='Detailed Results'!K27 -> 7 | U27: ='Detailed Results'!L27 -> 5 | V27: =IFERROR(U27/T27,"") -> 0.71428571 | W27: =IFERROR(U27/H27,"") -> 0.55555556 | X27: =IFERROR(2*V27*W27/(V27+W27),"") -> 0.625 | Y27: ='Detailed Results'!M27 -> 6 | Z27: ='Detailed Results'!N27 -> 6 | AA27: =IFERROR(Z27/Y27,"") -> 1 | AB27: =IFERROR(Z27/I27,"") -> 0.33333333 | AC27: =IFERROR(2*AA27*AB27/(AA27+AB27),"") -> 0.5
B28: Llama 3 | C28: T=0.2 | D28: 3 | E28: zero | F28: ='GT Input'!C4 -> 9 | G28: ='GT Input'!D4 -> 18 | H28: ='GT Input'!E4 -> 9 | I28: ='GT Input'!F4 -> 18 | J28: ='Detailed Results'!G28 -> 9 | K28: ='Detailed Results'!H28 -> 9 | L28: =IFERROR(K28/J28,"") -> 1 | M28: =IFERROR(K28/F28,"") -> 1 | N28: =IFERROR(2*L28*M28/(L28+M28),"") -> 1 | O28: ='Detailed Results'!I28 -> 18 | P28: ='Detailed Results'!J28 -> 18 | Q28: =IFERROR(P28/O28,"") -> 1 | R28: =IFERROR(P28/G28,"") -> 1 | S28: =IFERROR(2*Q28*R28/(Q28+R28),"") -> 1 | T28: ='Detailed Results'!K28 -> 9 | U28: ='Detailed Results'!L28 -> 9 | V28: =IFERROR(U28/T28,"") -> 1 | W28: =IFERROR(U28/H28,"") -> 1 | X28: =IFERROR(2*V28*W28/(V28+W28),"") -> 1 | Y28: ='Detailed Results'!M28 -> 18 | Z28: ='Detailed Results'!N28 -> 18 | AA28: =IFERROR(Z28/Y28,"") -> 1 | AB28: =IFERROR(Z28/I28,"") -> 1 | AC28: =IFERROR(2*AA28*AB28/(AA28+AB28),"") -> 1
B29: Llama 3 | C29: T=0.2 | D29: 3 | E29: one | F29: ='GT Input'!C4 -> 9 | G29: ='GT Input'!D4 -> 18 | H29: ='GT Input'!E4 -> 9 | I29: ='GT Input'!F4 -> 18 | J29: 7 | K29: 7 | L29: =IFERROR(K29/J29,"") -> 1 | M29: =IFERROR(K29/F29,"") -> 0.77777778 | N29: =IFERROR(2*L29*M29/(L29+M29),"") -> 0.875 | O29: ='Detailed Results'!I29 -> 6 | P29: ='Detailed Results'!J29 -> 6 | Q29: =IFERROR(P29/O29,"") -> 1 | R29: =IFERROR(P29/G29,"") -> 0.33333333 | S29: =IFERROR(2*Q29*R29/(Q29+R29),"") -> 0.5 | T29: ='Detailed Results'!K29 -> 7 | U29: ='Detailed Results'!L29 -> 5 | V29: =IFERROR(U29/T29,"") -> 0.71428571 | W29: =IFERROR(U29/H29,"") -> 0.55555556 | X29: =IFERROR(2*V29*W29/(V29+W29),"") -> 0.625 | Y29: ='Detailed Results'!M29 -> 6 | Z29: ='Detailed Results'!N29 -> 6 | AA29: =IFERROR(Z29/Y29,"") -> 1 | AB29: =IFERROR(Z29/I29,"") -> 0.33333333 | AC29: =IFERROR(2*AA29*AB29/(AA29+AB29),"") -> 0.5
B30: Llama 3 | C30: T=0.4 | D30: 1 | E30: zero | F30: ='GT Input'!C4 -> 9 | G30: ='GT Input'!D4 -> 18 | H30: ='GT Input'!E4 -> 9 | I30: ='GT Input'!F4 -> 18 | J30: ='Detailed Results'!G30 -> 7 | K30: ='Detailed Results'!H30 -> 7 | L30: =IFERROR(K30/J30,"") -> 1 | M30: =IFERROR(K30/F30,"") -> 0.77777778 | N30: =IFERROR(2*L30*M30/(L30+M30),"") -> 0.875 | O30: ='Detailed Results'!I30 -> 12 | P30: ='Detailed Results'!J30 -> 12 | Q30: =IFERROR(P30/O30,"") -> 1 | R30: =IFERROR(P30/G30,"") -> 0.66666667 | S30: =IFERROR(2*Q30*R30/(Q30+R30),"") -> 0.8 | T30: ='Detailed Results'!K30 -> 7 | U30: ='Detailed Results'!L30 -> 5 | V30: =IFERROR(U30/T30,"") -> 0.71428571 | W30: =IFERROR(U30/H30,"") -> 0.55555556 | X30: =IFERROR(2*V30*W30/(V30+W30),"") -> 0.625 | Y30: ='Detailed Results'!M30 -> 12 | Z30: ='Detailed Results'!N30 -> 12 | AA30: =IFERROR(Z30/Y30,"") -> 1 | AB30: =IFERROR(Z30/I30,"") -> 0.66666667 | AC30: =IFERROR(2*AA30*AB30/(AA30+AB30),"") -> 0.8
B31: Llama 3 | C31: T=0.4 | D31: 1 | E31: one | F31: ='GT Input'!C4 -> 9 | G31: ='GT Input'!D4 -> 18 | H31: ='GT Input'!E4 -> 9 | I31: ='GT Input'!F4 -> 18 | J31: 7 | K31: 7 | L31: =IFERROR(K31/J31,"") -> 1 | M31: =IFERROR(K31/F31,"") -> 0.77777778 | N31: =IFERROR(2*L31*M31/(L31+M31),"") -> 0.875 | O31: ='Detailed Results'!I31 -> 6 | P31: ='Detailed Results'!J31 -> 6 | Q31: =IFERROR(P31/O31,"") -> 1 | R31: =IFERROR(P31/G31,"") -> 0.33333333 | S31: =IFERROR(2*Q31*R31/(Q31+R31),"") -> 0.5 | T31: ='Detailed Results'!K31 -> 7 | U31: ='Detailed Results'!L31 -> 5 | V31: =IFERROR(U31/T31,"") -> 0.71428571 | W31: =IFERROR(U31/H31,"") -> 0.55555556 | X31: =IFERROR(2*V31*W31/(V31+W31),"") -> 0.625 | Y31: ='Detailed Results'!M31 -> 6 | Z31: ='Detailed Results'!N31 -> 6 | AA31: =IFERROR(Z31/Y31,"") -> 1 | AB31: =IFERROR(Z31/I31,"") -> 0.33333333 | AC31: =IFERROR(2*AA31*AB31/(AA31+AB31),"") -> 0.5
B32: Llama 3 | C32: T=0.4 | D32: 2 | E32: zero | F32: ='GT Input'!C4 -> 9 | G32: ='GT Input'!D4 -> 18 | H32: ='GT Input'!E4 -> 9 | I32: ='GT Input'!F4 -> 18 | J32: ='Detailed Results'!G32 -> 7 | K32: ='Detailed Results'!H32 -> 7 | L32: =IFERROR(K32/J32,"") -> 1 | M32: =IFERROR(K32/F32,"") -> 0.77777778 | N32: =IFERROR(2*L32*M32/(L32+M32),"") -> 0.875 | O32: ='Detailed Results'!I32 -> 12 | P32: ='Detailed Results'!J32 -> 12 | Q32: =IFERROR(P32/O32,"") -> 1 | R32: =IFERROR(P32/G32,"") -> 0.66666667 | S32: =IFERROR(2*Q32*R32/(Q32+R32),"") -> 0.8 | T32: ='Detailed Results'!K32 -> 7 | U32: ='Detailed Results'!L32 -> 5 | V32: =IFERROR(U32/T32,"") -> 0.71428571 | W32: =IFERROR(U32/H32,"") -> 0.55555556 | X32: =IFERROR(2*V32*W32/(V32+W32),"") -> 0.625 | Y32: ='Detailed Results'!M32 -> 12 | Z32: ='Detailed Results'!N32 -> 12 | AA32: =IFERROR(Z32/Y32,"") -> 1 | AB32: =IFERROR(Z32/I32,"") -> 0.66666667 | AC32: =IFERROR(2*AA32*AB32/(AA32+AB32),"") -> 0.8
B33: Llama 3 | C33: T=0.4 | D33: 2 | E33: one | F33: ='GT Input'!C4 -> 9 | G33: ='GT Input'!D4 -> 18 | H33: ='GT Input'!E4 -> 9 | I33: ='GT Input'!F4 -> 18 | J33: 7 | K33: 7 | L33: =IFERROR(K33/J33,"") -> 1 | M33: =IFERROR(K33/F33,"") -> 0.77777778 | N33: =IFERROR(2*L33*M33/(L33+M33),"") -> 0.875 | O33: ='Detailed Results'!I33 -> 6 | P33: ='Detailed Results'!J33 -> 6 | Q33: =IFERROR(P33/O33,"") -> 1 | R33: =IFERROR(P33/G33,"") -> 0.33333333 | S33: =IFERROR(2*Q33*R33/(Q33+R33),"") -> 0.5 | T33: ='Detailed Results'!K33 -> 7 | U33: ='Detailed Results'!L33 -> 5 | V33: =IFERROR(U33/T33,"") -> 0.71428571 | W33: =IFERROR(U33/H33,"") -> 0.55555556 | X33: =IFERROR(2*V33*W33/(V33+W33),"") -> 0.625 | Y33: ='Detailed Results'!M33 -> 6 | Z33: ='Detailed Results'!N33 -> 6 | AA33: =IFERROR(Z33/Y33,"") -> 1 | AB33: =IFERROR(Z33/I33,"") -> 0.33333333 | AC33: =IFERROR(2*AA33*AB33/(AA33+AB33),"") -> 0.5
B34: Llama 3 | C34: T=0.4 | D34: 3 | E34: zero | F34: ='GT Input'!C4 -> 9 | G34: ='GT Input'!D4 -> 18 | H34: ='GT Input'!E4 -> 9 | I34: ='GT Input'!F4 -> 18 | J34: ='Detailed Results'!G34 -> 7 | K34: ='Detailed Results'!H34 -> 7 | L34: =IFERROR(K34/J34,"") -> 1 | M34: =IFERROR(K34/F34,"") -> 0.77777778 | N34: =IFERROR(2*L34*M34/(L34+M34),"") -> 0.875 | O34: ='Detailed Results'!I34 -> 12 | P34: ='Detailed Results'!J34 -> 12 | Q34: =IFERROR(P34/O34,"") -> 1 | R34: =IFERROR(P34/G34,"") -> 0.66666667 | S34: =IFERROR(2*Q34*R34/(Q34+R34),"") -> 0.8 | T34: ='Detailed Results'!K34 -> 7 | U34: ='Detailed Results'!L34 -> 5 | V34: =IFERROR(U34/T34,"") -> 0.71428571 | W34: =IFERROR(U34/H34,"") -> 0.55555556 | X34: =IFERROR(2*V34*W34/(V34+W34),"") -> 0.625 | Y34: ='Detailed Results'!M34 -> 12 | Z34: ='Detailed Results'!N34 -> 12 | AA34: =IFERROR(Z34/Y34,"") -> 1 | AB34: =IFERROR(Z34/I34,"") -> 0.66666667 | AC34: =IFERROR(2*AA34*AB34/(AA34+AB34),"") -> 0.8
B35: Llama 3 | C35: T=0.4 | D35: 3 | E35: one | F35: ='GT Input'!C4 -> 9 | G35: ='GT Input'!D4 -> 18 | H35: ='GT Input'!E4 -> 9 | I35: ='GT Input'!F4 -> 18 | J35: 7 | K35: 7 | L35: =IFERROR(K35/J35,"") -> 1 | M35: =IFERROR(K35/F35,"") -> 0.77777778 | N35: =IFERROR(2*L35*M35/(L35+M35),"") -> 0.875 | O35: ='Detailed Results'!I35 -> 6 | P35: ='Detailed Results'!J35 -> 6 | Q35: =IFERROR(P35/O35,"") -> 1 | R35: =IFERROR(P35/G35,"") -> 0.33333333 | S35: =IFERROR(2*Q35*R35/(Q35+R35),"") -> 0.5 | T35: ='Detailed Results'!K35 -> 7 | U35: ='Detailed Results'!L35 -> 5 | V35: =IFERROR(U35/T35,"") -> 0.71428571 | W35: =IFERROR(U35/H35,"") -> 0.55555556 | X35: =IFERROR(2*V35*W35/(V35+W35),"") -> 0.625 | Y35: ='Detailed Results'!M35 -> 6 | Z35: ='Detailed Results'!N35 -> 6 | AA35: =IFERROR(Z35/Y35,"") -> 1 | AB35: =IFERROR(Z35/I35,"") -> 0.33333333 | AC35: =IFERROR(2*AA35*AB35/(AA35+AB35),"") -> 0.5
B36: Llama 3 | C36: T=0.6 | D36: 1 | E36: zero | F36: ='GT Input'!C4 -> 9 | G36: ='GT Input'!D4 -> 18 | H36: ='GT Input'!E4 -> 9 | I36: ='GT Input'!F4 -> 18 | J36: 7 | K36: 4 | L36: =IFERROR(K36/J36,"") -> 0.57142857 | M36: =IFERROR(K36/F36,"") -> 0.44444444 | N36: =IFERROR(2*L36*M36/(L36+M36),"") -> 0.5 | O36: ='Detailed Results'!I36 -> 5 | P36: ='Detailed Results'!J36 -> 5 | Q36: =IFERROR(P36/O36,"") -> 1 | R36: =IFERROR(P36/G36,"") -> 0.27777778 | S36: =IFERROR(2*Q36*R36/(Q36+R36),"") -> 0.43478261 | T36: ='Detailed Results'!K36 -> 7 | U36: ='Detailed Results'!L36 -> 5 | V36: =IFERROR(U36/T36,"") -> 0.71428571 | W36: =IFERROR(U36/H36,"") -> 0.55555556 | X36: =IFERROR(2*V36*W36/(V36+W36),"") -> 0.625 | Y36: ='Detailed Results'!M36 -> 5 | Z36: ='Detailed Results'!N36 -> 5 | AA36: =IFERROR(Z36/Y36,"") -> 1 | AB36: =IFERROR(Z36/I36,"") -> 0.27777778 | AC36: =IFERROR(2*AA36*AB36/(AA36+AB36),"") -> 0.43478261
B37: Llama 3 | C37: T=0.6 | D37: 1 | E37: one | F37: ='GT Input'!C4 -> 9 | G37: ='GT Input'!D4 -> 18 | H37: ='GT Input'!E4 -> 9 | I37: ='GT Input'!F4 -> 18 | J37: 7 | K37: 3 | L37: =IFERROR(K37/J37,"") -> 0.42857143 | M37: =IFERROR(K37/F37,"") -> 0.33333333 | N37: =IFERROR(2*L37*M37/(L37+M37),"") -> 0.375 | O37: ='Detailed Results'!I37 -> 5 | P37: ='Detailed Results'!J37 -> 5 | Q37: =IFERROR(P37/O37,"") -> 1 | R37: =IFERROR(P37/G37,"") -> 0.27777778 | S37: =IFERROR(2*Q37*R37/(Q37+R37),"") -> 0.43478261 | T37: ='Detailed Results'!K37 -> 7 | U37: ='Detailed Results'!L37 -> 5 | V37: =IFERROR(U37/T37,"") -> 0.71428571 | W37: =IFERROR(U37/H37,"") -> 0.55555556 | X37: =IFERROR(2*V37*W37/(V37+W37),"") -> 0.625 | Y37: ='Detailed Results'!M37 -> 5 | Z37: ='Detailed Results'!N37 -> 5 | AA37: =IFERROR(Z37/Y37,"") -> 1 | AB37: =IFERROR(Z37/I37,"") -> 0.27777778 | AC37: =IFERROR(2*AA37*AB37/(AA37+AB37),"") -> 0.43478261
B38: Llama 3 | C38: T=0.6 | D38: 2 | E38: zero | F38: ='GT Input'!C4 -> 9 | G38: ='GT Input'!D4 -> 18 | H38: ='GT Input'!E4 -> 9 | I38: ='GT Input'!F4 -> 18 | J38: 7 | K38: 4 | L38: =IFERROR(K38/J38,"") -> 0.57142857 | M38: =IFERROR(K38/F38,"") -> 0.44444444 | N38: =IFERROR(2*L38*M38/(L38+M38),"") -> 0.5 | O38: ='Detailed Results'!I38 -> 5 | P38: ='Detailed Results'!J38 -> 5 | Q38: =IFERROR(P38/O38,"") -> 1 | R38: =IFERROR(P38/G38,"") -> 0.27777778 | S38: =IFERROR(2*Q38*R38/(Q38+R38),"") -> 0.43478261 | T38: ='Detailed Results'!K38 -> 7 | U38: ='Detailed Results'!L38 -> 5 | V38: =IFERROR(U38/T38,"") -> 0.71428571 | W38: =IFERROR(U38/H38,"") -> 0.55555556 | X38: =IFERROR(2*V38*W38/(V38+W38),"") -> 0.625 | Y38: ='Detailed Results'!M38 -> 5 | Z38: ='Detailed Results'!N38 -> 5 | AA38: =IFERROR(Z38/Y38,"") -> 1 | AB38: =IFERROR(Z38/I38,"") -> 0.27777778 | AC38: =IFERROR(2*AA38*AB38/(AA38+AB38),"") -> 0.43478261
B39: Llama 3 | C39: T=0.6 | D39: 2 | E39: one | F39: ='GT Input'!C4 -> 9 | G39: ='GT Input'!D4 -> 18 | H39: ='GT Input'!E4 -> 9 | I39: ='GT Input'!F4 -> 18 | J39: 7 | K39: 7 | L39: =IFERROR(K39/J39,"") -> 1 | M39: =IFERROR(K39/F39,"") -> 0.77777778 | N39: =IFERROR(2*L39*M39/(L39+M39),"") -> 0.875 | O39: ='Detailed Results'!I39 -> 13 | P39: ='Detailed Results'!J39 -> 13 | Q39: =IFERROR(P39/O39,"") -> 1 | R39: =IFERROR(P39/G39,"") -> 0.72222222 | S39: =IFERROR(2*Q39*R39/(Q39+R39),"") -> 0.83870968 | T39: ='Detailed Results'!K39 -> 7 | U39: ='Detailed Results'!L39 -> 5 | V39: =IFERROR(U39/T39,"") -> 0.71428571 | W39: =IFERROR(U39/H39,"") -> 0.55555556 | X39: =IFERROR(2*V39*W39/(V39+W39),"") -> 0.625 | Y39: ='Detailed Results'!M39 -> 13 | Z39: ='Detailed Results'!N39 -> 13 | AA39: =IFERROR(Z39/Y39,"") -> 1 | AB39: =IFERROR(Z39/I39,"") -> 0.72222222 | AC39: =IFERROR(2*AA39*AB39/(AA39+AB39),"") -> 0.83870968
B40: Llama 3 | C40: T=0.6 | D40: 3 | E40: zero | F40: ='GT Input'!C4 -> 9 | G40: ='GT Input'!D4 -> 18 | H40: ='GT Input'!E4 -> 9 | I40: ='GT Input'!F4 -> 18 | J40: 9 | K40: 9 | L40: =IFERROR(K40/J40,"") -> 1 | M40: =IFERROR(K40/F40,"") -> 1 | N40: =IFERROR(2*L40*M40/(L40+M40),"") -> 1 | O40: ='Detailed Results'!I40 -> 18 | P40: ='Detailed Results'!J40 -> 18 | Q40: =IFERROR(P40/O40,"") -> 1 | R40: =IFERROR(P40/G40,"") -> 1 | S40: =IFERROR(2*Q40*R40/(Q40+R40),"") -> 1 | T40: ='Detailed Results'!K40 -> 9 | U40: ='Detailed Results'!L40 -> 9 | V40: =IFERROR(U40/T40,"") -> 1 | W40: =IFERROR(U40/H40,"") -> 1 | X40: =IFERROR(2*V40*W40/(V40+W40),"") -> 1 | Y40: ='Detailed Results'!M40 -> 18 | Z40: ='Detailed Results'!N40 -> 18 | AA40: =IFERROR(Z40/Y40,"") -> 1 | AB40: =IFERROR(Z40/I40,"") -> 1 | AC40: =IFERROR(2*AA40*AB40/(AA40+AB40),"") -> 1
...

Sheet Summary (Avg per LLM)
A1: Summary — Average Metrics per Description × LLM
A2: Averages over all temperatures (0.2/0.4/0.6), iterations (1/2/3), and prompts (1/2) — 18 runs per LLM per description
C3: Syntactic DRD | F3: Syntactic DT | I3: Semantic DRD | L3: Semantic DT
A4: Source | B4: LLM | C4: Avg P | D4: Avg R | E4: Avg F1 | F4: Avg P | G4: Avg R | H4: Avg F1 | I4: Avg P | J4: Avg R | K4: Avg F1 | L4: Avg P | M4: Avg R | N4: Avg F1
A5: Description 01 | B5: Gemini | C5: =AVERAGE('GT Comparison'!L6:L23) -> 0.85101131 | D5: =AVERAGE('GT Comparison'!M6:M23) -> 0.61111111 | E5: =AVERAGE('GT Comparison'!N6:N23) -> 0.72200257 | F5: =AVERAGE('GT Comparison'!Q6:Q23) -> 1 | G5: =AVERAGE('GT Comparison'!R6:R23) -> 0.66666667 | H5: =AVERAGE('GT Comparison'!S6:S23) -> 0.8 | I5: =AVERAGE('GT Comparison'!V6:V23) -> 0.78095238 | J5: =AVERAGE('GT Comparison'!W6:W23) -> 0.5308642 | K5: =AVERAGE('GT Comparison'!X6:X23) -> 0.62797619 | L5: =AVERAGE('GT Comparison'!AA6:AA23) -> 1 | M5: =AVERAGE('GT Comparison'!AB6:AB23) -> 0.66666667 | N5: =AVERAGE('GT Comparison'!AC6:AC23) -> 0.8
B6: Llama 3 | C6: =AVERAGE('GT Comparison'!L24:L41) -> 0.8968254 | D6: =AVERAGE('GT Comparison'!M24:M41) -> 0.74691358 | E6: =AVERAGE('GT Comparison'!N24:N41) -> 0.8125 | F6: =AVERAGE('GT Comparison'!Q24:Q41) -> 0.99074074 | G6: =AVERAGE('GT Comparison'!R24:R41) -> 0.5462963 | H6: =AVERAGE('GT Comparison'!S24:S41) -> 0.66442912 | I6: =AVERAGE('GT Comparison'!V24:V41) -> 0.77777778 | J6: =AVERAGE('GT Comparison'!W24:W41) -> 0.65432099 | K6: =AVERAGE('GT Comparison'!X24:X41) -> 0.70833333 | L6: =AVERAGE('GT Comparison'!AA24:AA41) -> 1 | M6: =AVERAGE('GT Comparison'!AB24:AB41) -> 0.54938272 | N6: =AVERAGE('GT Comparison'!AC24:AC41) -> 0.66905875
B7: Mistral | C7: =AVERAGE('GT Comparison'!L42:L59) -> 0.93125701 | D7: =AVERAGE('GT Comparison'!M42:M59) -> 0.82098765 | E7: =AVERAGE('GT Comparison'!N42:N59) -> 0.86304337 | F7: =AVERAGE('GT Comparison'!Q42:Q59) -> 1 | G7: =AVERAGE('GT Comparison'!R42:R59) -> 0.75308642 | H7: =AVERAGE('GT Comparison'!S42:S59) -> 0.85095785 | I7: =AVERAGE('GT Comparison'!V42:V59) -> 0.7557199 | J7: =AVERAGE('GT Comparison'!W42:W59) -> 0.68518519 | K7: =AVERAGE('GT Comparison'!X42:X59) -> 0.71189828 | L7: =AVERAGE('GT Comparison'!AA42:AA59) -> 0.97222222 | M7: =AVERAGE('GT Comparison'!AB42:AB59) -> 0.72530864 | N7: =AVERAGE('GT Comparison'!AC42:AC59) -> 0.82318008
A8: Description 02 | B8: Gemini | C8: =AVERAGE('GT Comparison'!L60:L77) -> 1 | D8: =AVERAGE('GT Comparison'!M60:M77) -> 1 | E8: =AVERAGE('GT Comparison'!N60:N77) -> 1 | F8: =AVERAGE('GT Comparison'!Q60:Q77) -> 1 | G8: =AVERAGE('GT Comparison'!R60:R77) -> 1.2407407 | H8: =AVERAGE('GT Comparison'!S60:S77) -> 1.1062824 | I8: =AVERAGE('GT Comparison'!V60:V77) -> 1 | J8: =AVERAGE('GT Comparison'!W60:W77) -> 1 | K8: =AVERAGE('GT Comparison'!X60:X77) -> 1 | L8: =AVERAGE('GT Comparison'!AA60:AA77) -> 0.91218324 | M8: =AVERAGE('GT Comparison'!AB60:AB77) -> 1.137037 | N8: =AVERAGE('GT Comparison'!AC60:AC77) -> 1.0114288
B9: Llama 3 | C9: =AVERAGE('GT Comparison'!L78:L95) -> 1 | D9: =AVERAGE('GT Comparison'!M78:M95) -> 1 | E9: =AVERAGE('GT Comparison'!N78:N95) -> 1 | F9: =AVERAGE('GT Comparison'!Q78:Q95) -> 1 | G9: =AVERAGE('GT Comparison'!R78:R95) -> 1.0074074 | H9: =AVERAGE('GT Comparison'!S78:S95) -> 1.0029778 | I9: =AVERAGE('GT Comparison'!V78:V95) -> 1 | J9: =AVERAGE('GT Comparison'!W78:W95) -> 1 | K9: =AVERAGE('GT Comparison'!X78:X95) -> 1 | L9: =AVERAGE('GT Comparison'!AA78:AA95) -> 0.87689076 | M9: =AVERAGE('GT Comparison'!AB78:AB95) -> 0.88518519 | N9: =AVERAGE('GT Comparison'!AC78:AC95) -> 0.88041033
B10: Mistral | C10: =AVERAGE('GT Comparison'!L96:L113) -> 1 | D10: =AVERAGE('GT Comparison'!M96:M113) -> 0.99382716 | E10: =AVERAGE('GT Comparison'!N96:N113) -> 0.99673203 | F10: =AVERAGE('GT Comparison'!Q96:Q113) -> 0.99603175 | G10: =AVERAGE('GT Comparison'!R96:R113) -> 0.99259259 | H10: =AVERAGE('GT Comparison'!S96:S113) -> 0.9933993 | I10: =AVERAGE('GT Comparison'!V96:V113) -> 1 | J10: =AVERAGE('GT Comparison'!W96:W113) -> 0.99382716 | K10: =AVERAGE('GT Comparison'!X96:X113) -> 0.99673203 | L10: =AVERAGE('GT Comparison'!AA96:AA113) -> 0.93683862 | M10: =AVERAGE('GT Comparison'!AB96:AB113) -> 0.93333333 | N10: =AVERAGE('GT Comparison'!AC96:AC113) -> 0.93421832
A11: Description 03 | B11: Gemini | C11: =AVERAGE('GT Comparison'!L114:L131) -> 0.99851852 | D11: =AVERAGE('GT Comparison'!M114:M131) -> 0.86868687 | E11: =AVERAGE('GT Comparison'!N114:N131) -> 0.92798326 | F11: =AVERAGE('GT Comparison'!Q114:Q131) -> 1 | G11: =AVERAGE('GT Comparison'!R114:R131) -> 1.002924 | H11: =AVERAGE('GT Comparison'!S114:S131) -> 0.99790616 | I11: =AVERAGE('GT Comparison'!V114:V131) -> 0.83950617 | J11: =AVERAGE('GT Comparison'!W114:W131) -> 0.73737374 | K11: =AVERAGE('GT Comparison'!X114:X131) -> 0.78333333 | L11: =AVERAGE('GT Comparison'!AA114:AA131) -> 0.5631235 | M11: =AVERAGE('GT Comparison'!AB114:AB131) -> 0.59356725 | N11: =AVERAGE('GT Comparison'!AC114:AC131) -> 0.57555398
B12: Llama 3 | C12: =AVERAGE('GT Comparison'!L132:L149) -> 0.98877666 | D12: =AVERAGE('GT Comparison'!M132:M149) -> 0.77272727 | E12: =AVERAGE('GT Comparison'!N132:N149) -> 0.86564475 | F12: =AVERAGE('GT Comparison'!Q132:Q149) -> 1 | G12: =AVERAGE('GT Comparison'!R132:R149) -> 0.69298246 | H12: =AVERAGE('GT Comparison'!S132:S149) -> 0.80803129 | I12: =AVERAGE('GT Comparison'!V132:V149) -> 0.7595198 | J12: =AVERAGE('GT Comparison'!W132:W149) -> 0.5959596 | K12: =AVERAGE('GT Comparison'!X132:X149) -> 0.66637722 | L12: =AVERAGE('GT Comparison'!AA132:AA149) -> 0.56310541 | M12: =AVERAGE('GT Comparison'!AB132:AB149) -> 0.37426901 | N12: =AVERAGE('GT Comparison'!AC132:AC149) -> 0.43977768
B13: Mistral | C13: =AVERAGE('GT Comparison'!L150:L167) -> 0.96296296 | D13: =AVERAGE('GT Comparison'!M150:M167) -> 0.80808081 | E13: =AVERAGE('GT Comparison'!N150:N167) -> 0.87777778 | F13: =AVERAGE('GT Comparison'!Q150:Q167) -> 1 | G13: =AVERAGE('GT Comparison'!R150:R167) -> 0.71052632 | H13: =AVERAGE('GT Comparison'!S150:S167) -> 0.82158428 | I13: =AVERAGE('GT Comparison'!V150:V167) -> 0.7654321 | J13: =AVERAGE('GT Comparison'!W150:W167) -> 0.64646465 | K13: =AVERAGE('GT Comparison'!X150:X167) -> 0.7 | L13: =AVERAGE('GT Comparison'!AA150:AA167) -> 0.61303044 | M13: =AVERAGE('GT Comparison'!AB150:AB167) -> 0.43567251 | N13: =AVERAGE('GT Comparison'!AC150:AC167) -> 0.50140462
A14: Description 04 | B14: Gemini | C14: =AVERAGE('GT Comparison'!L168:L185) -> 1 | D14: =AVERAGE('GT Comparison'!M168:M185) -> 1 | E14: =AVERAGE('GT Comparison'!N168:N185) -> 1 | F14: =AVERAGE('GT Comparison'!Q168:Q185) -> 1 | G14: =AVERAGE('GT Comparison'!R168:R185) -> 0.62426901 | H14: =AVERAGE('GT Comparison'!S168:S185) -> 0.76329765 | I14: =AVERAGE('GT Comparison'!V168:V185) -> 1 | J14: =AVERAGE('GT Comparison'!W168:W185) -> 1 | K14: =AVERAGE('GT Comparison'!X168:X185) -> 1 | L14: =AVERAGE('GT Comparison'!AA168:AA185) -> 1 | M14: =AVERAGE('GT Comparison'!AB168:AB185) -> 0.62426901 | N14: =AVERAGE('GT Comparison'!AC168:AC185) -> 0.76329765
B15: Llama 3 | C15: =AVERAGE('GT Comparison'!L186:L203) -> 1 | D15: =AVERAGE('GT Comparison'!M186:M203) -> 1 | E15: =AVERAGE('GT Comparison'!N186:N203) -> 1 | F15: =AVERAGE('GT Comparison'!Q186:Q203) -> 1 | G15: =AVERAGE('GT Comparison'!R186:R203) -> 0.46637427 | H15: =AVERAGE('GT Comparison'!S186:S203) -> 0.63311899 | I15: =AVERAGE('GT Comparison'!V186:V203) -> 1 | J15: =AVERAGE('GT Comparison'!W186:W203) -> 1 | K15: =AVERAGE('GT Comparison'!X186:X203) -> 1 | L15: =AVERAGE('GT Comparison'!AA186:AA203) -> 0.96031746 | M15: =AVERAGE('GT Comparison'!AB186:AB203) -> 0.44444444 | N15: =AVERAGE('GT Comparison'!AC186:AC203) -> 0.6048704
B16: Mistral | C16: =AVERAGE('GT Comparison'!L204:L221) -> 1 | D16: =AVERAGE('GT Comparison'!M204:M221) -> 1 | E16: =AVERAGE('GT Comparison'!N204:N221) -> 1 | F16: =AVERAGE('GT Comparison'!Q204:Q221) -> 1 | G16: =AVERAGE('GT Comparison'!R204:R221) -> 0.44444444 | H16: =AVERAGE('GT Comparison'!S204:S221) -> 0.6119874 | I16: =AVERAGE('GT Comparison'!V204:V221) -> 1 | J16: =AVERAGE('GT Comparison'!W204:W221) -> 1 | K16: =AVERAGE('GT Comparison'!X204:X221) -> 1 | L16: =AVERAGE('GT Comparison'!AA204:AA221) -> 1 | M16: =AVERAGE('GT Comparison'!AB204:AB221) -> 0.44444444 | N16: =AVERAGE('GT Comparison'!AC204:AC221) -> 0.6119874
A17: Description 05 | B17: Gemini | C17: =AVERAGE('GT Comparison'!L222:L239) -> 1 | D17: =AVERAGE('GT Comparison'!M222:M239) -> 1 | E17: =AVERAGE('GT Comparison'!N222:N239) -> 1 | F17: =AVERAGE('GT Comparison'!Q222:Q239) -> 1 | G17: =AVERAGE('GT Comparison'!R222:R239) -> 0.77160494 | H17: =AVERAGE('GT Comparison'!S222:S239) -> 0.87083333 | I17: =AVERAGE('GT Comparison'!V222:V239) -> 1 | J17: =AVERAGE('GT Comparison'!W222:W239) -> 1 | K17: =AVERAGE('GT Comparison'!X222:X239) -> 1 | L17: =AVERAGE('GT Comparison'!AA222:AA239) -> 0.57671958 | M17: =AVERAGE('GT Comparison'!AB222:AB239) -> 0.44444444 | N17: =AVERAGE('GT Comparison'!AC222:AC239) -> 0.50185185
B18: Llama 3 | C18: =AVERAGE('GT Comparison'!L240:L257) -> 1 | D18: =AVERAGE('GT Comparison'!M240:M257) -> 1.2592593 | E18: =AVERAGE('GT Comparison'!N240:N257) -> 1.0972222 | F18: =AVERAGE('GT Comparison'!Q240:Q257) -> 1 | G18: =AVERAGE('GT Comparison'!R240:R257) -> 0.85185185 | H18: =AVERAGE('GT Comparison'!S240:S257) -> 0.91309585 | I18: =AVERAGE('GT Comparison'!V240:V257) -> 0.84444444 | J18: =AVERAGE('GT Comparison'!W240:W257) -> 1 | K18: =AVERAGE('GT Comparison'!X240:X257) -> 0.90277778 | L18: =AVERAGE('GT Comparison'!AA240:AA257) -> 0.50643739 | M18: =AVERAGE('GT Comparison'!AB240:AB257) -> 0.41975309 | N18: =AVERAGE('GT Comparison'!AC240:AC257) -> 0.45529073
B19: Mistral | C19: =AVERAGE('GT Comparison'!L258:L275) -> 1 | D19: =AVERAGE('GT Comparison'!M258:M275) -> 1.0740741 | E19: =AVERAGE('GT Comparison'!N258:N275) -> 1.0277778 | F19: =AVERAGE('GT Comparison'!Q258:Q275) -> 1 | G19: =AVERAGE('GT Comparison'!R258:R275) -> 0.91975309 | H19: =AVERAGE('GT Comparison'!S258:S275) -> 0.95039429 | I19: =AVERAGE('GT Comparison'!V258:V275) -> 0.95555556 | J19: =AVERAGE('GT Comparison'!W258:W275) -> 1 | K19: =AVERAGE('GT Comparison'!X258:X275) -> 0.97222222 | L19: =AVERAGE('GT Comparison'!AA258:AA275) -> 0.4973545 | M19: =AVERAGE('GT Comparison'!AB258:AB275) -> 0.44444444 | N19: =AVERAGE('GT Comparison'!AC258:AC275) -> 0.46649143
A20: Description 06 | B20: Gemini | C20: =AVERAGE('GT Comparison'!L276:L293) -> 1 | D20: =AVERAGE('GT Comparison'!M276:M293) -> 0.55555556 | E20: =AVERAGE('GT Comparison'!N276:N293) -> 0.71428571 | F20: =AVERAGE('GT Comparison'!Q276:Q293) -> 1 | G20: =AVERAGE('GT Comparison'!R276:R293) -> 0.61538462 | H20: =AVERAGE('GT Comparison'!S276:S293) -> 0.76190476 | I20: =AVERAGE('GT Comparison'!V276:V293) -> 0.6 | J20: =AVERAGE('GT Comparison'!W276:W293) -> 0.33333333 | K20: =AVERAGE('GT Comparison'!X276:X293) -> 0.42857143 | L20: =AVERAGE('GT Comparison'!AA276:AA293) -> 0.625 | M20: =AVERAGE('GT Comparison'!AB276:AB293) -> 0.38461538 | N20: =AVERAGE('GT Comparison'!AC276:AC293) -> 0.47619048
B21: Llama 3 | C21: =AVERAGE('GT Comparison'!L294:L311) -> 0.85555556 | D21: =AVERAGE('GT Comparison'!M294:M311) -> 0.47530864 | E21: =AVERAGE('GT Comparison'!N294:N311) -> 0.61111111 | F21: =AVERAGE('GT Comparison'!Q294:Q311) -> 1 | G21: =AVERAGE('GT Comparison'!R294:R311) -> 0.63675214 | H21: =AVERAGE('GT Comparison'!S294:S311) -> 0.77753728 | I21: =AVERAGE('GT Comparison'!V294:V311) -> 0.6 | J21: =AVERAGE('GT Comparison'!W294:W311) -> 0.33333333 | K21: =AVERAGE('GT Comparison'!X294:X311) -> 0.42857143 | L21: =AVERAGE('GT Comparison'!AA294:AA311) -> 0.60570988 | M21: =AVERAGE('GT Comparison'!AB294:AB311) -> 0.38461538 | N21: =AVERAGE('GT Comparison'!AC294:AC311) -> 0.47017797
B22: Mistral | C22: =AVERAGE('GT Comparison'!L312:L329) -> 1 | D22: =AVERAGE('GT Comparison'!M312:M329) -> 0.55555556 | E22: =AVERAGE('GT Comparison'!N312:N329) -> 0.71428571 | F22: =AVERAGE('GT Comparison'!Q312:Q329) -> 1 | G22: =AVERAGE('GT Comparison'!R312:R329) -> 0.61538462 | H22: =AVERAGE('GT Comparison'!S312:S329) -> 0.76190476 | I22: =AVERAGE('GT Comparison'!V312:V329) -> 0.6 | J22: =AVERAGE('GT Comparison'!W312:W329) -> 0.33333333 | K22: =AVERAGE('GT Comparison'!X312:X329) -> 0.42857143 | L22: =AVERAGE('GT Comparison'!AA312:AA329) -> 0.625 | M22: =AVERAGE('GT Comparison'!AB312:AB329) -> 0.38461538 | N22: =AVERAGE('GT Comparison'!AC312:AC329) -> 0.47619048
A23: Description 07 | B23: Gemini | C23: =AVERAGE('GT Comparison'!L330:L347) -> 1 | D23: =AVERAGE('GT Comparison'!M330:M347) -> 1 | E23: =AVERAGE('GT Comparison'!N330:N347) -> 1 | F23: =AVERAGE('GT Comparison'!Q330:Q347) -> 1 | G23: =AVERAGE('GT Comparison'!R330:R347) -> 0.83333333 | H23: =AVERAGE('GT Comparison'!S330:S347) -> 0.9042141 | I23: =AVERAGE('GT Comparison'!V330:V347) -> 1 | J23: =AVERAGE('GT Comparison'!W330:W347) -> 1 | K23: =AVERAGE('GT Comparison'!X330:X347) -> 1 | L23: =AVERAGE('GT Comparison'!AA330:AA347) -> 1 | M23: =AVERAGE('GT Comparison'!AB330:AB347) -> 0.83333333 | N23: =AVERAGE('GT Comparison'!AC330:AC347) -> 0.9042141
B24: Llama 3 | C24: =AVERAGE('GT Comparison'!L348:L365) -> 1 | D24: =AVERAGE('GT Comparison'!M348:M365) -> 1 | E24: =AVERAGE('GT Comparison'!N348:N365) -> 1 | F24: =AVERAGE('GT Comparison'!Q348:Q365) -> 1 | G24: =AVERAGE('GT Comparison'!R348:R365) -> 0.60802469 | H24: =AVERAGE('GT Comparison'!S348:S365) -> 0.75615764 | I24: =AVERAGE('GT Comparison'!V348:V365) -> 1 | J24: =AVERAGE('GT Comparison'!W348:W365) -> 1 | K24: =AVERAGE('GT Comparison'!X348:X365) -> 1 | L24: =AVERAGE('GT Comparison'!AA348:AA365) -> 0.81767677 | M24: =AVERAGE('GT Comparison'!AB348:AB365) -> 0.49691358 | N24: =AVERAGE('GT Comparison'!AC348:AC365) -> 0.61808976
B25: Mistral | C25: =AVERAGE('GT Comparison'!L366:L383) -> 1 | D25: =AVERAGE('GT Comparison'!M366:M383) -> 1 | E25: =AVERAGE('GT Comparison'!N366:N383) -> 1 | F25: =AVERAGE('GT Comparison'!Q366:Q383) -> 1 | G25: =AVERAGE('GT Comparison'!R366:R383) -> 0.62654321 | H25: =AVERAGE('GT Comparison'!S366:S383) -> 0.76911479 | I25: =AVERAGE('GT Comparison'!V366:V383) -> 1 | J25: =AVERAGE('GT Comparison'!W366:W383) -> 1 | K25: =AVERAGE('GT Comparison'!X366:X383) -> 1 | L25: =AVERAGE('GT Comparison'!AA366:AA383) -> 0.83821549 | M25: =AVERAGE('GT Comparison'!AB366:AB383) -> 0.52777778 | N25: =AVERAGE('GT Comparison'!AC366:AC383) -> 0.64649118
A26: Description 08 | B26: Gemini | C26: =AVERAGE('GT Comparison'!L384:L401) -> 1 | D26: =AVERAGE('GT Comparison'!M384:M401) -> 1.015873 | E26: =AVERAGE('GT Comparison'!N384:N401) -> 1.0069444 | F26: =AVERAGE('GT Comparison'!Q384:Q401) -> 1 | G26: =AVERAGE('GT Comparison'!R384:R401) -> 0.95454545 | H26: =AVERAGE('GT Comparison'!S384:S401) -> 0.97492063 | I26: =AVERAGE('GT Comparison'!V384:V401) -> 0.94797178 | J26: =AVERAGE('GT Comparison'!W384:W401) -> 0.96031746 | K26: =AVERAGE('GT Comparison'!X384:X401) -> 0.95337302 | L26: =AVERAGE('GT Comparison'!AA384:AA401) -> 0.82936508 | M26: =AVERAGE('GT Comparison'!AB384:AB401) -> 0.78787879 | N26: =AVERAGE('GT Comparison'!AC384:AC401) -> 0.80708995
B27: Llama 3 | C27: =AVERAGE('GT Comparison'!L402:L419) -> 0.87469937 | D27: =AVERAGE('GT Comparison'!M402:M419) -> 0.93650794 | E27: =AVERAGE('GT Comparison'!N402:N419) -> 0.90141093 | F27: =AVERAGE('GT Comparison'!Q402:Q419) -> 0.99494949 | G27: =AVERAGE('GT Comparison'!R402:R419) -> 0.8989899 | H27: =AVERAGE('GT Comparison'!S402:S419) -> 0.93387289 | I27: =AVERAGE('GT Comparison'!V402:V419) -> 0.73481842 | J27: =AVERAGE('GT Comparison'!W402:W419) -> 0.77777778 | K27: =AVERAGE('GT Comparison'!X402:X419) -> 0.75319665 | L27: =AVERAGE('GT Comparison'!AA402:AA419) -> 0.83232323 | M27: =AVERAGE('GT Comparison'!AB402:AB419) -> 0.73737374 | N27: =AVERAGE('GT Comparison'!AC402:AC419) -> 0.77189075
B28: Mistral | C28: =AVERAGE('GT Comparison'!L420:L437) -> 1 | D28: =AVERAGE('GT Comparison'!M420:M437) -> 1.031746 | E28: =AVERAGE('GT Comparison'!N420:N437) -> 1.0148148 | F28: =AVERAGE('GT Comparison'!Q420:Q437) -> 1 | G28: =AVERAGE('GT Comparison'!R420:R437) -> 0.92929293 | H28: =AVERAGE('GT Comparison'!S420:S437) -> 0.96212754 | I28: =AVERAGE('GT Comparison'!V420:V437) -> 0.97222222 | J28: =AVERAGE('GT Comparison'!W420:W437) -> 1 | K28: =AVERAGE('GT Comparison'!X420:X437) -> 0.98518519 | L28: =AVERAGE('GT Comparison'!AA420:AA437) -> 0.94949495 | M28: =AVERAGE('GT Comparison'!AB420:AB437) -> 0.87878788 | N28: =AVERAGE('GT Comparison'!AC420:AC437) -> 0.91162249
A29: Description 09 | B29: Gemini | C29: =AVERAGE('GT Comparison'!L438:L455) -> 1 | D29: =AVERAGE('GT Comparison'!M438:M455) -> 1 | E29: =AVERAGE('GT Comparison'!N438:N455) -> 1 | F29: =AVERAGE('GT Comparison'!Q438:Q455) -> 1 | G29: =AVERAGE('GT Comparison'!R438:R455) -> 1.037037 | H29: =AVERAGE('GT Comparison'!S438:S455) -> 1.015873 | I29: =AVERAGE('GT Comparison'!V438:V455) -> 1 | J29: =AVERAGE('GT Comparison'!W438:W455) -> 1 | K29: =AVERAGE('GT Comparison'!X438:X455) -> 1 | L29: =AVERAGE('GT Comparison'!AA438:AA455) -> 0.73726852 | M29: =AVERAGE('GT Comparison'!AB438:AB455) -> 0.75925926 | N29: =AVERAGE('GT Comparison'!AC438:AC455) -> 0.74669312
B30: Llama 3 | C30: =AVERAGE('GT Comparison'!L456:L473) -> 0.95061728 | D30: =AVERAGE('GT Comparison'!M456:M473) -> 0.95061728 | E30: =AVERAGE('GT Comparison'!N456:N473) -> 0.95061728 | F30: =AVERAGE('GT Comparison'!Q456:Q473) -> 1 | G30: =AVERAGE('GT Comparison'!R456:R473) -> 0.97685185 | H30: =AVERAGE('GT Comparison'!S456:S473) -> 0.96658312 | I30: =AVERAGE('GT Comparison'!V456:V473) -> 0.95061728 | J30: =AVERAGE('GT Comparison'!W456:W473) -> 0.95061728 | K30: =AVERAGE('GT Comparison'!X456:X473) -> 0.95061728 | L30: =AVERAGE('GT Comparison'!AA456:AA473) -> 0.71990741 | M30: =AVERAGE('GT Comparison'!AB456:AB473) -> 0.65277778 | N30: =AVERAGE('GT Comparison'!AC456:AC473) -> 0.66764133
B31: Mistral | C31: =AVERAGE('GT Comparison'!L474:L491) -> 1 | D31: =AVERAGE('GT Comparison'!M474:M491) -> 1 | E31: =AVERAGE('GT Comparison'!N474:N491) -> 1 | F31: =AVERAGE('GT Comparison'!Q474:Q491) -> 1 | G31: =AVERAGE('GT Comparison'!R474:R491) -> 1.0833333 | H31: =AVERAGE('GT Comparison'!S474:S491) -> 1.031677 | I31: =AVERAGE('GT Comparison'!V474:V491) -> 1 | J31: =AVERAGE('GT Comparison'!W474:W491) -> 1 | K31: =AVERAGE('GT Comparison'!X474:X491) -> 1 | L31: =AVERAGE('GT Comparison'!AA474:AA491) -> 0.65719697 | M31: =AVERAGE('GT Comparison'!AB474:AB491) -> 0.69444444 | N31: =AVERAGE('GT Comparison'!AC474:AC491) -> 0.66935818
A32: Description 10 | B32: Gemini | C32: =AVERAGE('GT Comparison'!L492:L509) -> 1 | D32: =AVERAGE('GT Comparison'!M492:M509) -> 1.0793651 | E32: =AVERAGE('GT Comparison'!N492:N509) -> 1.0347222 | F32: =AVERAGE('GT Comparison'!Q492:Q509) -> 1 | G32: =AVERAGE('GT Comparison'!R492:R509) -> 0.81349206 | H32: =AVERAGE('GT Comparison'!S492:S509) -> 0.89378284 | I32: =AVERAGE('GT Comparison'!V492:V509) -> 0.90740741 | J32: =AVERAGE('GT Comparison'!W492:W509) -> 0.96031746 | K32: =AVERAGE('GT Comparison'!X492:X509) -> 0.93055556 | L32: =AVERAGE('GT Comparison'!AA492:AA509) -> 0.79630439 | M32: =AVERAGE('GT Comparison'!AB492:AB509) -> 0.62698413 | N32: =AVERAGE('GT Comparison'!AC492:AC509) -> 0.69977841
B33: Llama 3 | C33: =AVERAGE('GT Comparison'!L510:L527) -> 0.98765432 | D33: =AVERAGE('GT Comparison'!M510:M527) -> 1.1587302 | E33: =AVERAGE('GT Comparison'!N510:N527) -> 1.0625 | F33: =AVERAGE('GT Comparison'!Q510:Q527) -> 1 | G33: =AVERAGE('GT Comparison'!R510:R527) -> 0.80952381 | H33: =AVERAGE('GT Comparison'!S510:S527) -> 0.8941817 | I33: =AVERAGE('GT Comparison'!V510:V527) -> 0.80864198 | J33: =AVERAGE('GT Comparison'!W510:W527) -> 0.92857143 | K33: =AVERAGE('GT Comparison'!X510:X527) -> 0.86111111 | L33: =AVERAGE('GT Comparison'!AA510:AA527) -> 0.62406112 | M33: =AVERAGE('GT Comparison'!AB510:AB527) -> 0.5 | N33: =AVERAGE('GT Comparison'!AC510:AC527) -> 0.55493511
B34: Mistral | C34: =AVERAGE('GT Comparison'!L528:L545) -> 1 | D34: =AVERAGE('GT Comparison'!M528:M545) -> 1.0079365 | E34: =AVERAGE('GT Comparison'!N528:N545) -> 1.0037037 | F34: =AVERAGE('GT Comparison'!Q528:Q545) -> 1 | G34: =AVERAGE('GT Comparison'!R528:R545) -> 0.78174603 | H34: =AVERAGE('GT Comparison'!S528:S545) -> 0.8767831 | I34: =AVERAGE('GT Comparison'!V528:V545) -> 0.98611111 | J34: =AVERAGE('GT Comparison'!W528:W545) -> 0.99206349 | K34: =AVERAGE('GT Comparison'!X528:X545) -> 0.98888889 | L34: =AVERAGE('GT Comparison'!AA528:AA545) -> 0.8599046 | M34: =AVERAGE('GT Comparison'!AB528:AB545) -> 0.67063492 | N34: =AVERAGE('GT Comparison'!AC528:AC545) -> 0.75296358
